<?xml version="1.0" encoding="utf-8"?><testsuites><testsuite name="pytest" errors="1" failures="0" skipped="0" tests="1" time="0.032" timestamp="2024-07-26T09:25:25.294017" hostname="LAPTOP-IN3BP6Q4"><testcase classname="pytest" name="internal" time="0.000"><error message="internal error">Traceback (most recent call last):
  File "C:\Users\kika\OneDrive\Desktop\python\frameworkPython\.venv\lib\site-packages\_pytest\main.py", line 285, in wrap_session
    session.exitstatus = doit(config, session) or 0
  File "C:\Users\kika\OneDrive\Desktop\python\frameworkPython\.venv\lib\site-packages\_pytest\main.py", line 338, in _main
    config.hook.pytest_collection(session=session)
  File "C:\Users\kika\OneDrive\Desktop\python\frameworkPython\.venv\lib\site-packages\pluggy\_hooks.py", line 513, in __call__
    return self._hookexec(self.name, self._hookimpls.copy(), kwargs, firstresult)
  File "C:\Users\kika\OneDrive\Desktop\python\frameworkPython\.venv\lib\site-packages\pluggy\_manager.py", line 120, in _hookexec
    return self._inner_hookexec(hook_name, methods, kwargs, firstresult)
  File "C:\Users\kika\OneDrive\Desktop\python\frameworkPython\.venv\lib\site-packages\pluggy\_callers.py", line 139, in _multicall
    raise exception.with_traceback(exception.__traceback__)
  File "C:\Users\kika\OneDrive\Desktop\python\frameworkPython\.venv\lib\site-packages\pluggy\_callers.py", line 122, in _multicall
    teardown.throw(exception)  # type: ignore[union-attr]
  File "C:\Users\kika\OneDrive\Desktop\python\frameworkPython\.venv\lib\site-packages\_pytest\logging.py", line 794, in pytest_collection
    return (yield)
  File "C:\Users\kika\OneDrive\Desktop\python\frameworkPython\.venv\lib\site-packages\pluggy\_callers.py", line 122, in _multicall
    teardown.throw(exception)  # type: ignore[union-attr]
  File "C:\Users\kika\OneDrive\Desktop\python\frameworkPython\.venv\lib\site-packages\_pytest\warnings.py", line 120, in pytest_collection
    return (yield)
  File "C:\Users\kika\OneDrive\Desktop\python\frameworkPython\.venv\lib\site-packages\pluggy\_callers.py", line 122, in _multicall
    teardown.throw(exception)  # type: ignore[union-attr]
  File "C:\Users\kika\OneDrive\Desktop\python\frameworkPython\.venv\lib\site-packages\_pytest\config\__init__.py", line 1424, in pytest_collection
    return (yield)
  File "C:\Users\kika\OneDrive\Desktop\python\frameworkPython\.venv\lib\site-packages\pluggy\_callers.py", line 103, in _multicall
    res = hook_impl.function(*args)
  File "C:\Users\kika\OneDrive\Desktop\python\frameworkPython\.venv\lib\site-packages\_pytest\main.py", line 349, in pytest_collection
    session.perform_collect()
  File "C:\Users\kika\OneDrive\Desktop\python\frameworkPython\.venv\lib\site-packages\_pytest\main.py", line 813, in perform_collect
    self.config.pluginmanager.check_pending()
  File "C:\Users\kika\OneDrive\Desktop\python\frameworkPython\.venv\lib\site-packages\pluggy\_manager.py", line 391, in check_pending
    raise PluginValidationError(
pluggy._manager.PluginValidationError: unknown hook 'pytest_html_report_name' in plugin &lt;module 'test.conftest' from 'C:\\Users\\kika\\OneDrive\\Desktop\\python\\frameworkPython\\test\\conftest.py'&gt;</error></testcase></testsuite></testsuites>